<?xml version="1.0" ?>

<robot name="vr">

    <material name="grey">
        <color rgba="0.97 0.97 0.97 1"/>
    </material>

    <material name="black">
        <color rgba="0 0 0 1"/>
    </material>



    <link name="base_link">
        <visual>
          <origin rpy="0 0 0" xyz="0 0 0.0625" />
          <geometry>
            <box size ="0.4 0.3 0.015"/> 
          </geometry>

          <material name="grey"/>
        </visual>


        <collision>
            <origin rpy="0 0 0" xyz="0 0 0.0625" />
            <geometry>
              <box size ="0.4 0.3 0.015"/> 
            </geometry>
        </collision>

        <visual>
            <origin rpy="0 0 0" xyz="0.19 0.14 0.035" />
            <geometry>
                <cylinder radius="0.01" length="0.07" />
            </geometry>   
          
        </visual>

        <collision>
           <origin rpy="0 0 0" xyz="0.19 0.14 0.035" />
            <geometry>
                <cylinder radius="0.01" length="0.07" />
            </geometry> 
        </collision>

        <visual>
            <origin rpy="0 0 0" xyz="-0.19 0.14 0.035" />
            <geometry>
                <cylinder radius="0.01" length="0.07" />
            </geometry>   
           
        </visual>

        <collision>
            <origin rpy="0 0 0" xyz="-0.19 0.14 0.035" />
            <geometry>
                <cylinder radius="0.01" length="0.07" />
            </geometry> 
        </collision>
        <visual>
            <origin rpy="0 0 0" xyz="0.19 -0.14 0.035" />
            <geometry>
                <cylinder radius="0.01" length="0.07" />
            </geometry>   
           
        </visual>

        <collision>
            <origin rpy="0 0 0" xyz="0.19 -0.14 0.035" />
            <geometry>
                <cylinder radius="0.01" length="0.07" />
            </geometry>  
        </collision>

        <visual>
            <origin rpy="0 0 0" xyz="-0.19 -0.14 0.035" />
            <geometry>
                <cylinder radius="0.01" length="0.07" />
            </geometry>   
           
        </visual>

        <collision>
            <origin rpy="0 0 0" xyz="-0.19 -0.14 0.035" />
            <geometry>
                <cylinder radius="0.01" length="0.07" />
            </geometry>   
        </collision>
    </link>


    
    <joint name="base_link__link_01" type="revolute">
        <axis xyz="0 0 1"/>
        <limit effort="1000.0" lower="-3.14" upper="3.14" velocity="0.5"/>
        <origin rpy="0 0 0" xyz="0 0 0.07"/>
        <parent link="base_link"/>
        <child link="link_01"/>
        
    </joint>

    <link name="link_01">
        <visual>
            <origin rpy="0 0 0" xyz="0 0 0.0105" />
            <geometry>
                <cylinder radius="0.043" length="0.021" />
            </geometry>   
            <material name="grey"/>
        </visual>

        <collision>
            <origin rpy="0 0 0" xyz="0 0 0.0105" />
            <geometry>
                <cylinder radius="0.043" length="0.021" />
            </geometry> 
        </collision>

        <visual>
            <origin rpy="0 0 0" xyz="0 0 0.026" />
            <geometry>
                <cylinder radius="0.023" length="0.01" />
            </geometry>   
        </visual>

        <collision>
           <origin rpy="0 0 0" xyz="0 0 0.026" />
            <geometry>
                <cylinder radius="0.023" length="0.01" />
            </geometry>
        </collision>

        <visual>
            <origin rpy="0 0 0" xyz="0 0 0.0385" />
            <geometry>
                <box size ="0.120 0.120 0.015"/>  
            </geometry>
            
        </visual>

        <collision>
            <origin rpy="0 0 0" xyz="0 0 0.0385" />
            <geometry>
                <box size ="0.120 0.120 0.015"/>  
            </geometry>
        </collision>
        
        <visual>
            <origin rpy="0 0 0" xyz="0 0.052 0.0785" />
            <geometry>
                <box size ="0.120 0.012 0.065"/>  
            </geometry>
            
        </visual>

        <collision>
            <origin rpy="0 0 0" xyz="0 0.052 0.0785" />
            <geometry>
                <box size ="0.120 0.012 0.065"/>  
            </geometry>
        </collision>
       
        <visual>
            <origin rpy="0 0 0" xyz="0.06 0.052 0.1385" />
            <geometry>
                <box size ="0.074 0.012 0.055"/>  
            </geometry>
            
        </visual>

       <collision>
             <origin rpy="0 0 0" xyz="0.06 0.052 0.1385" />
            <geometry>
                <box size ="0.074 0.012 0.055"/>  
            </geometry>
       </collision>

        <visual>
            <origin rpy="0 0 0" xyz="0.0 -0.052 0.0785" />
            <geometry>
                <box size ="0.120 0.012 0.065"/>  
            </geometry>
            
        </visual>

        <collision>
            <origin rpy="0 0 0" xyz="0.0 -0.052 0.0785" />
            <geometry>
                <box size ="0.120 0.012 0.065"/>  
            </geometry>
        </collision>

        <visual>
            <origin rpy="0 0 0" xyz="0.06 -0.052 0.1385" />
            <geometry>
                <box size ="0.074 0.012 0.055"/>  
            </geometry>
            
        </visual>

        <collision>
           <origin rpy="0 0 0" xyz="0.06 -0.052 0.1385" />
            <geometry>
                <box size ="0.074 0.012 0.055"/>  
            </geometry>
        </collision>

       
        <visual>
            <origin rpy="1.57 0 0" xyz="0.06 -0.052 0.166" />
            <geometry>
                <cylinder radius="0.037" length="0.012"/>  
            </geometry>
            <material name="black"/>

        </visual>

        <collision>
            <origin rpy="1.57 0 0" xyz="0.06 -0.052 0.166" />
            <geometry>
                <cylinder radius="0.037" length="0.012"/>  
            </geometry>
        </collision>

      
        <visual>
            <origin rpy="1.57 0 0" xyz="0.06 0.052 0.166" />
            <geometry>
                <cylinder radius="0.037" length="0.012"/>  
            </geometry>
            <material name="black"/>
        </visual>

        <collision>
            <origin rpy="1.57 0 0" xyz="0.06 0.052 0.166" />
            <geometry>
                <cylinder radius="0.037" length="0.012"/>  
            </geometry>
        </collision>


        <visual>
            <origin rpy="0 0 0" xyz="0.06 0 0.106" />
            <geometry>
                <box size ="0.074 0.092 0.01"/>  
            </geometry>
            
        </visual>

        <collision>
            <origin rpy="0 0 0" xyz="0.06 0 0.106" />
            <geometry>
                <box size ="0.074 0.092 0.01"/>  
            </geometry>
        </collision>

       

        <visual>
            <origin rpy="0 0 0" xyz="0.06 -0.019 0.1385" />
            <geometry>
                <box size ="0.06 0.01 0.055"/>  
            </geometry>
            
        </visual>

        <collision>
           <origin rpy="0 0 0" xyz="0.06 -0.019 0.1385" />
            <geometry>
                <box size ="0.06 0.01 0.055"/>  
            </geometry>
        </collision>

      
        <visual>
            <origin rpy="0 0 0" xyz="0.06 0.026 0.1385" />
            <geometry>
                <box size ="0.06 0.01 0.055"/>  
            </geometry>
            
        </visual>
        <collision>
            <origin rpy="0 0 0" xyz="0.06 0.026 0.1385" />
            <geometry>
                <box size ="0.06 0.01 0.055"/>  
            </geometry>
        </collision>


        <visual>
            <origin rpy="1.57 0 0" xyz="0.06 0.026 0.166" />
            <geometry>
                <cylinder radius="0.03" length="0.01"/>  
            </geometry>
            <material name="black"/>
           

        </visual>

        <collision>
             <origin rpy="1.57 0 0" xyz="0.06 0.026 0.166" />
            <geometry>
                <cylinder radius="0.03" length="0.01"/>  
            </geometry>
        </collision>

        <visual>
            <origin rpy="1.57 0 0" xyz="0.06 -0.019 0.166" />
            <geometry>
                <cylinder radius="0.03" length="0.01"/>  
            </geometry>
            <material name="black"/>

        </visual>

        <collision>
            <origin rpy="1.57 0 0" xyz="0.06 -0.019 0.166" />
            <geometry>
                <cylinder radius="0.03" length="0.01"/>  
            </geometry>
        </collision>

 
    </link>

    <joint name="link_01__link_02" type="revolute">
        <axis xyz="0 0 1"/>
        <limit effort="1000.0" lower="-3.14" upper="3.14" velocity="0.5"/>
        <origin rpy="1.57 0 0" xyz="0.06 0 0.166"/>
        <parent link="link_01"/>
    
        <child link="link_02"/>
    </joint> 

    <link name="link_02">

        <visual>
            <origin rpy="0 0 0" xyz="0 0 0.074" />
            <geometry>
                <cylinder radius="0.037" length="0.032"/>  
            </geometry>
            <material name="black"/>
           
        </visual>

        <collision>
            <origin rpy="0 0 0" xyz="0 0 0.074" />
            <geometry>
                <cylinder radius="0.037" length="0.032"/>  
            </geometry> 
        </collision>

        <visual>
            <origin rpy="0 0 0" xyz="0 0 -0.074" />
            <geometry>
                <cylinder radius="0.037" length="0.032"/>  
            </geometry>
            <material name="black"/>
           
        </visual>

        <collision>
           <origin rpy="0 0 0" xyz="0 0 -0.074" />
            <geometry>
                <cylinder radius="0.037" length="0.032"/>  
            </geometry>
        </collision>

    </link>

    <joint name="link_02__link_02_par" type="fixed">
        <origin rpy="0 0 0" xyz="0 0.11 0"/>
        <parent link="link_02"/>
        <child link="link_02_par"/>
    </joint>

    <link name="link_02_par">

       <visual>
            <origin rpy="0 0 0" xyz="0 0 0.0345" />
            <geometry>
                <box size ="0.040 0.220 0.015"/>  
            </geometry>
  
            <material name="grey"/>
        </visual>

       <collision>
            <origin rpy="0 0 0" xyz="0 0 0.0345" />
            <geometry>
                <box size ="0.040 0.220 0.015"/>  
            </geometry>
        </collision>
        
        <visual>
            <origin rpy="0 0 0" xyz="0 -0.11 0.041" />
            <geometry>
                <cylinder radius="0.025" length="0.034"/>  
            </geometry>
            
        </visual>

       <collision>
             <origin rpy="0 0 0" xyz="0 -0.11 0.041" />
            <geometry>
                <cylinder radius="0.025" length="0.034"/>  
            </geometry>
        </collision>

        <visual>
            <origin rpy="0 0 0" xyz="0 -0.11 -0.0445" />
            <geometry>
                <cylinder radius="0.025" length="0.027"/>  
            </geometry>
           
        </visual>

        <collision>
            <origin rpy="0 0 0" xyz="0 -0.11 -0.0445" />
            <geometry>
                <cylinder radius="0.025" length="0.027"/>  
            </geometry>
        </collision>

        <!--
        <visual>
            <origin rpy="0 0 0" xyz="-0.1035 0.0 -0.029" />
            <geometry>
                <box size ="0.027 0.220 0.008"/>  
            </geometry>
  
            <material name="grey"/>
        </visual>

        <collision>
            <origin rpy="0 0 0" xyz="-0.1035 0.0 -0.029" />
            <geometry>
                <box size ="0.027 0.220 0.008"/>  
            </geometry>
        </collision>
        -->

    </link>

    <joint name="link_02__link_02_mim" type="revolute">
        <axis xyz="0 0 1"/>
        <limit effort="1000.0" lower="-3.14" upper="3.14" velocity="0.5"/>
        <origin rpy="0 0 1.57" xyz="0 0.220 0"/>
        <parent link="link_02"/>
        <child link="link_02_mim"/>
        <mimic joint="link_01__link_02" multiplier="-1" offset="0" />
    </joint>

    <link name="link_02_mim">
        <!--
        <visual>
            <origin rpy="0 0 0" xyz="0.0511198 -0.023 0" />
            <geometry>
                <box size ="0.0752396 0.014 0.051"/>  
            </geometry>
            <material name="grey"/>
    
        </visual>  

        <collision>
            <origin rpy="0 0 0" xyz="0.0511198 -0.023 0" />
            <geometry>
                <box size ="0.0752396 0.014 0.051"/>  
            </geometry>
        </collision>

        <visual>
            <origin rpy="0 0 0" xyz="-0.22 0.045 -0.038" />
            <geometry>
                <box size ="0.027 0.09 0.008"/>  
            </geometry>
            <material name="grey"/>
    
        </visual>  

        <collision>
            <origin rpy="0 0 0" xyz="-0.22 0.045 -0.038" />
            <geometry>
                <box size ="0.027 0.09 0.008"/>  
            </geometry>
        </collision>

        <visual>
            <origin rpy="0 0 0" xyz="0.0 0.045 -0.021" />
            <geometry>
                <box size ="0.027 0.09 0.008"/>  
            </geometry>
            <material name="grey"/>
    
        </visual>  

        <collision>
            <origin rpy="0 0 0" xyz="0.0 0.045 -0.021" />
            <geometry>
                <box size ="0.027 0.09 0.008"/>  
            </geometry>
        </collision>


        <visual>
            <origin rpy="0 0 0" xyz="0.0095 0.00724 0.0" />
            <geometry>
                <box size ="0.008 0.0745 0.051"/>  
            </geometry>
            <material name="grey"/>
    
        </visual>  

        <collision>
             <origin rpy="0 0 0" xyz="0.0095 0.00724 0.0" />
            <geometry>
                <box size ="0.008 0.0745 0.051"/>  
            </geometry>
        </collision>
        -->

        <visual>
            <origin rpy="0 0 0" xyz="0 0.0 0.0" />
            <geometry>
                <cylinder radius="0.0135" length="0.051"/>  
            </geometry>
            <material name="grey"/>
        </visual>

        <collision>
           <origin rpy="0 0 0" xyz="0 0.0 0.0" />
            <geometry>
                <cylinder radius="0.0135" length="0.051"/>  
            </geometry>
        </collision>

    </link>

    <joint name="link_02_mim__link_03" type="revolute">
        <axis xyz="0 0 1"/>
        <limit effort="1000.0" lower="-3.14" upper="3.14" velocity="0.5"/>
        <origin rpy="0 0 0" xyz="0.0 0.0 0.0"/>
        <parent link="link_02_mim"/>
        <child link="link_03"/>
    </joint>


    <link name="link_03">
        
        <visual>
            <origin rpy="0 0 0" xyz="0.0511198 -0.023 0" />
            <geometry>
                <box size ="0.0752396 0.014 0.051"/>  
            </geometry>
            <material name="grey"/>
    
        </visual>  

        <collision>
            <origin rpy="0 0 0" xyz="0.0511198 -0.023 0" />
            <geometry>
                <box size ="0.0752396 0.014 0.051"/>  
            </geometry>
        </collision>

       <!-- <visual>
            <origin rpy="0 0 0" xyz="-0.22 0.045 -0.038" />
            <geometry>
                <box size ="0.027 0.09 0.008"/>  
            </geometry>
            <material name="grey"/>
    
        </visual>  

        <collision>
            <origin rpy="0 0 0" xyz="-0.22 0.045 -0.038" />
            <geometry>
                <box size ="0.027 0.09 0.008"/>  
            </geometry>
        </collision>
-->
        <visual>
            <origin rpy="0 0 0" xyz="0.0 0.045 -0.021" />
            <geometry>
                <box size ="0.027 0.09 0.008"/>  
            </geometry>
            <material name="grey"/>
    
        </visual>  

        <collision>
            <origin rpy="0 0 0" xyz="0.0 0.045 -0.021" />
            <geometry>
                <box size ="0.027 0.09 0.008"/>  
            </geometry>
        </collision>


        <visual>
            <origin rpy="0 0 0" xyz="0.0095 0.00724 0.0" />
            <geometry>
                <box size ="0.008 0.0745 0.051"/>  
            </geometry>
            <material name="grey"/>
    
        </visual>  

        <collision>
             <origin rpy="0 0 0" xyz="0.0095 0.00724 0.0" />
            <geometry>
                <box size ="0.008 0.0745 0.051"/>  
            </geometry>
        </collision>
        
    </link>








    <joint name="link_01__link_03_mim" type="revolute">
        <axis xyz="0 0 1"/>
        <limit effort="1000.0" lower="-3.14" upper="3.14" velocity="0.5"/>
        <origin rpy="1.57 0 0" xyz="0.06 0 0.166"/>
        <parent link="link_01"/>
        <child link="link_03_mim"/>
        <mimic joint="link_02_mim__link_03" multiplier="1" offset="0" />
        
    </joint>


    <link name="link_03_mim">
        <visual>
            <origin rpy="0 0 0" xyz="-0.045 0.00 -0.038" />
            <geometry>
                <box size ="0.09 0.042 0.008"/>  
            </geometry>
            <material name="grey"/>
    
        </visual>  

        <collision>
           <origin rpy="0 0 0" xyz="-0.045 0.00 -0.038" />
            <geometry>
                <box size ="0.09 0.042 0.008"/>  
            </geometry>
        </collision>

        <visual>
            <origin rpy="0 0 0.35" xyz="-0.12 -0.011 -0.038" />
            <geometry>
                <box size ="0.064 0.042 0.008"/>  
            </geometry>
            <material name="grey"/>
    
        </visual> 
        
        <collision>
            <origin rpy="0 0 0.35" xyz="-0.12 -0.011 -0.038" />
            <geometry>
                <box size ="0.064 0.042 0.008"/>  
            </geometry>
           
          </collision>

        <visual>
            <origin rpy="0 0 0" xyz="-0.09 0.0 -0.038" />
            <geometry>
                <cylinder radius="0.021" length="0.008" />
            </geometry>
            <material name="grey"/>
        </visual>

	<collision>
            <origin rpy="0 0 0" xyz="-0.09 0.0 -0.038" />
            <geometry>
                <cylinder radius="0.021" length="0.008" />
            </geometry>
           
          </collision>

        <visual>
            <origin rpy="0 0 0" xyz="-0.151 -0.022 -0.0085" />
            <geometry>
                <cylinder radius="0.021" length="0.067" />
            </geometry>
            <material name="grey"/>
        </visual>

	<collision>
             <origin rpy="0 0 0" xyz="-0.151 -0.022 -0.0085" />
            <geometry>
                <cylinder radius="0.021" length="0.067" />
            </geometry>
           
          </collision>

    </link>






    <joint name="link_03__link_04" type="revolute">
        <axis xyz="0 0 1"/>
        <limit effort="1000.0" lower="-3.14" upper="3.14" velocity="0.5"/>
        <origin rpy="1.57 0 0" xyz="0.0615 -0.03 0"/>
        <parent link="link_03"/>
        <child link="link_04"/>
    </joint>

    <link name="link_04">
        <visual>
            <origin rpy="0 0 0" xyz="0 0 0.1435" />
            <geometry>
                <cylinder radius="0.015" length="0.287" />
            </geometry>
            <material name="grey"/>
        </visual>


        <collision>
            <origin rpy="0 0 0" xyz="0 0 0.1435" />
            <geometry>
                <cylinder radius="0.015" length="0.287" />
            </geometry>
          </collision>


          <visual>
            <origin rpy="0 0 0" xyz="0 0 0.329" />
            <geometry>
                <box size ="0.06 0.06 0.08"/>  
            </geometry>
            <material name="grey"/>
               
        </visual>

        <collision>
              <origin rpy="0 0 0" xyz="0 0 0.329" />
            <geometry>
                <box size ="0.06 0.06 0.08"/>  
            </geometry>
          </collision>
    </link>
    
    
    
    
    <joint name="link_04__link_05" type="revolute">
        <axis xyz="0 0 1"/>
        <limit effort="1000.0" lower="-3.14" upper="3.14" velocity="0.5"/>
        <origin rpy="-1.57 0 0" xyz="0 0 0.345"/>
        <parent link="link_04"/>
        <child link="link_05"/>
    </joint>

    <link name="link_05">

        <visual>
            <origin rpy="0 0 0" xyz="0 0 0" />
            <geometry>
                <cylinder radius="0.0225" length="0.055" />
            </geometry>
            <material name="black"/>
        </visual>
       
        
        <collision>
             <origin rpy="0 0 0" xyz="0 0 0" />
            <geometry>
                <cylinder radius="0.0225" length="0.055" />
            </geometry>
        </collision>
 
    </link> 

   

    
    <joint name="link_05__link_06" type="revolute">
        <axis xyz="0 0 1"/>
        <limit effort="1000.0" lower="-3.14" upper="3.14" velocity="0.5"/>
        <origin rpy="1.57 0 0" xyz="0 -0.1025 0"/>
        <parent link="link_05"/>
        <child link="link_06"/>
    </joint>

    <link name="link_06">
        <visual>
            <origin rpy="0 0 0" xyz="0 0 -0.04" />
            <geometry>
                <box size ="0.028 0.02 0.08"/>  
            </geometry>
            <material name="grey"/>
               
        </visual>

        <collision>
             <origin rpy="0 0 0" xyz="0 0 -0.04" />
            <geometry>
                <box size ="0.028 0.02 0.08"/>  
            </geometry>
        </collision>


       
    </link>
   
</robot>
